Workbook
Name Orders: #REF!
Name People: #REF!
Name Returns: #REF!

Sheet Sheet1
A3: Row Labels | B3: Count of Sales
A4: Furniture | B4: 208
A5: null | B5: 2
A6: Office Supplies | B6: 604
A7: Technology | B7: 190
A8: Grand Total | B8: 1004

Sheet Sales data
A1: Row ID | B1: Order ID | C1: Day | D1: Month | E1: Year | F1: Ship Mode | G1: Customer ID | H1: Customer Name | I1: Segment | J1: Country-State-City | K1: Region | L1: Postal Code | M1: Product ID | N1: Category | O1: Sub-Category | P1: Product Name | Q1: Sales | R1: Quantity | S1: Discount | T1: Profit
A2: 1 | B2: CA-2020-152156 | C2: 8 | D2: 11 | E2: 2020 | F2: Second Class | G2: CG-12520 | H2: claire gute | I2: Consumer | J2: United States-Kentucky-Henderson | K2: South | L2: 42420 | M2: FUR-BO-10001798 | N2: Furniture | O2: Bookcases | P2: Bush Somerset Collection Bookcase | Q2: =_xlfn.XLOOKUP(Table3[[#This Row],[Product Name]],Sales!A:A,Sales!B:B) -> 261.96 | R2: =_xlfn.XLOOKUP(Table3[[#This Row],[Product Name]],Sales!A:A,Sales!C:C) -> 2 | S2: =_xlfn.XLOOKUP(Table3[[#This Row],[Product Name]],Sales!A:A,Sales!D:D) -> 0 | T2: =_xlfn.XLOOKUP(Table3[[#This Row],[Product Name]],Sales!A:A,Sales!E:E) -> 41.9136
A3: 2 | B3: CA-2020-152156 | C3: 8 | D3: 11 | E3: 2020 | F3: Second Class | G3: CG-12520 | H3: claire gute | I3: Consumer | J3: United States-Kentucky-Henderson | K3: South | L3: 42420 | M3: FUR-CH-10000454 | N3: Furniture | O3: Chairs | P3: Hon Deluxe Fabric Upholstered Stacking Chairs, Rounded Back | Q3: =_xlfn.XLOOKUP(Table3[[#This Row],[Product Name]],Sales!A:A,Sales!B:B) -> 731.94 | R3: =_xlfn.XLOOKUP(Table3[[#This Row],[Product Name]],Sales!A:A,Sales!C:C) -> 3 | S3: =_xlfn.XLOOKUP(Table3[[#This Row],[Product Name]],Sales!A:A,Sales!D:D) -> 0 | T3: =_xlfn.XLOOKUP(Table3[[#This Row],[Product Name]],Sales!A:A,Sales!E:E) -> 219.582
A4: 3 | B4: CA-2020-138688 | C4: 12 | D4: 6 | E4: 2020 | F4: Second Class | G4: DV-13045 | H4: darrin van huff | I4: Corporate | J4: United States-California-Los Angeles | K4: West | L4: 90036 | M4: OFF-LA-10000240 | N4: Office Supplies | O4: Labels | P4: Self-Adhesive Address Labels for Typewriters by Universal | Q4: =_xlfn.XLOOKUP(Table3[[#This Row],[Product Name]],Sales!A:A,Sales!B:B) -> 14.62 | R4: =_xlfn.XLOOKUP(Table3[[#This Row],[Product Name]],Sales!A:A,Sales!C:C) -> 2 | S4: =_xlfn.XLOOKUP(Table3[[#This Row],[Product Name]],Sales!A:A,Sales!D:D) -> 0 | T4: =_xlfn.XLOOKUP(Table3[[#This Row],[Product Name]],Sales!A:A,Sales!E:E) -> 6.8714
A5: 4 | B5: US-2019-108966 | C5: 11 | D5: 10 | E5: 2019 | F5: Standard Class | G5: SO-20335 | H5: sean o'donnell | I5: Consumer | J5: United States-Florida-Fort Lauderdale | K5: South | L5: 33311 | M5: FUR-TA-10000577 | N5: Furniture | O5: Tables | P5: Bretford CR4500 Series Slim Rectangular Table | Q5: =_xlfn.XLOOKUP(Table3[[#This Row],[Product Name]],Sales!A:A,Sales!B:B) -> 957.5775 | R5: =_xlfn.XLOOKUP(Table3[[#This Row],[Product Name]],Sales!A:A,Sales!C:C) -> 5 | S5: =_xlfn.XLOOKUP(Table3[[#This Row],[Product Name]],Sales!A:A,Sales!D:D) -> 0.45 | T5: =_xlfn.XLOOKUP(Table3[[#This Row],[Product Name]],Sales!A:A,Sales!E:E) -> -383.031
A6: 5 | B6: US-2019-108966 | C6: 11 | D6: 10 | E6: 2019 | F6: Standard Class | G6: SO-20335 | H6: sean o'donnell | I6: Consumer | J6: United States-Florida-Fort Lauderdale | K6: South | L6: 33311 | M6: OFF-ST-10000760 | N6: Office Supplies | O6: Storage | P6: Eldon Fold 'N Roll Cart System | Q6: =_xlfn.XLOOKUP(Table3[[#This Row],[Product Name]],Sales!A:A,Sales!B:B) -> 22.368 | R6: =_xlfn.XLOOKUP(Table3[[#This Row],[Product Name]],Sales!A:A,Sales!C:C) -> 2 | S6: =_xlfn.XLOOKUP(Table3[[#This Row],[Product Name]],Sales!A:A,Sales!D:D) -> 0.2 | T6: =_xlfn.XLOOKUP(Table3[[#This Row],[Product Name]],Sales!A:A,Sales!E:E) -> 2.5164
A7: 6 | B7: CA-2018-115812 | C7: 9 | D7: 6 | E7: 2018 | F7: Standard Class | G7: BH-11710 | H7: brosina hoffman | I7: Consumer | J7: United States-California-Los Angeles | K7: West | L7: 90032 | M7: FUR-FU-10001487 | N7: Furniture | O7: Furnishings | P7: Eldon Expressions Wood and Plastic Desk Accessories, Cherry Wood | Q7: =_xlfn.XLOOKUP(Table3[[#This Row],[Product Name]],Sales!A:A,Sales!B:B) -> 48.86 | R7: =_xlfn.XLOOKUP(Table3[[#This Row],[Product Name]],Sales!A:A,Sales!C:C) -> 7 | S7: =_xlfn.XLOOKUP(Table3[[#This Row],[Product Name]],Sales!A:A,Sales!D:D) -> 0 | T7: =_xlfn.XLOOKUP(Table3[[#This Row],[Product Name]],Sales!A:A,Sales!E:E) -> 14.1694
A8: 7 | B8: CA-2018-115812 | C8: 9 | D8: 6 | E8: 2018 | F8: Standard Class | G8: BH-11710 | H8: brosina hoffman | I8: Consumer | J8: United States-California-Los Angeles | K8: West | L8: 90032 | M8: OFF-AR-10002833 | N8: Office Supplies | O8: Art | P8: Newell 322 | Q8: =_xlfn.XLOOKUP(Table3[[#This Row],[Product Name]],Sales!A:A,Sales!B:B) -> 7.28 | R8: =_xlfn.XLOOKUP(Table3[[#This Row],[Product Name]],Sales!A:A,Sales!C:C) -> 4 | S8: =_xlfn.XLOOKUP(Table3[[#This Row],[Product Name]],Sales!A:A,Sales!D:D) -> 0 | T8: =_xlfn.XLOOKUP(Table3[[#This Row],[Product Name]],Sales!A:A,Sales!E:E) -> 1.9656
A9: 8 | B9: CA-2018-115812 | C9: 9 | D9: 6 | E9: 2018 | F9: Standard Class | G9: BH-11710 | H9: brosina hoffman | I9: Consumer | J9: United States-California-Los Angeles | K9: West | L9: 90032 | M9: TEC-PH-10002275 | N9: Technology | O9: Phones | P9: Mitel 5320 IP Phone VoIP phone | Q9: =_xlfn.XLOOKUP(Table3[[#This Row],[Product Name]],Sales!A:A,Sales!B:B) -> 907.152 | R9: =_xlfn.XLOOKUP(Table3[[#This Row],[Product Name]],Sales!A:A,Sales!C:C) -> 6 | S9: =_xlfn.XLOOKUP(Table3[[#This Row],[Product Name]],Sales!A:A,Sales!D:D) -> 0.2 | T9: =_xlfn.XLOOKUP(Table3[[#This Row],[Product Name]],Sales!A:A,Sales!E:E) -> 90.7152
A10: 9 | B10: CA-2018-115812 | C10: 9 | D10: 6 | E10: 2018 | F10: Standard Class | G10: BH-11710 | H10: brosina hoffman | I10: Consumer | J10: United States-California-Los Angeles | K10: West | L10: 90032 | M10: OFF-BI-10003910 | N10: Office Supplies | O10: Binders | P10: DXL Angle-View Binders with Locking Rings by Samsill | Q10: =_xlfn.XLOOKUP(Table3[[#This Row],[Product Name]],Sales!A:A,Sales!B:B) -> 18.504 | R10: =_xlfn.XLOOKUP(Table3[[#This Row],[Product Name]],Sales!A:A,Sales!C:C) -> 3 | S10: =_xlfn.XLOOKUP(Table3[[#This Row],[Product Name]],Sales!A:A,Sales!D:D) -> 0.2 | T10: =_xlfn.XLOOKUP(Table3[[#This Row],[Product Name]],Sales!A:A,Sales!E:E) -> 5.7825
A11: 10 | B11: CA-2018-115812 | C11: 9 | D11: 6 | E11: 2018 | F11: Standard Class | G11: BH-11710 | H11: brosina hoffman | I11: Consumer | J11: United States-California-Los Angeles | K11: West | L11: 90032 | M11: OFF-AP-10002892 | N11: Office Supplies | O11: Appliances | P11: Belkin F5C206VTEL 6 Outlet Surge | Q11: =_xlfn.XLOOKUP(Table3[[#This Row],[Product Name]],Sales!A:A,Sales!B:B) -> 114.9 | R11: =_xlfn.XLOOKUP(Table3[[#This Row],[Product Name]],Sales!A:A,Sales!C:C) -> 5 | S11: =_xlfn.XLOOKUP(Table3[[#This Row],[Product Name]],Sales!A:A,Sales!D:D) -> 0 | T11: =_xlfn.XLOOKUP(Table3[[#This Row],[Product Name]],Sales!A:A,Sales!E:E) -> 34.47
A12: 11 | B12: CA-2018-115812 | C12: 9 | D12: 6 | E12: 2018 | F12: Standard Class | G12: BH-11710 | H12: brosina hoffman | I12: Consumer | J12: United States-California-Los Angeles | K12: West | L12: 90032 | M12: FUR-TA-10001539 | N12: Furniture | O12: Tables | P12: Chromcraft Rectangular Conference Tables | Q12: =_xlfn.XLOOKUP(Table3[[#This Row],[Product Name]],Sales!A:A,Sales!B:B) -> 1706.184 | R12: =_xlfn.XLOOKUP(Table3[[#This Row],[Product Name]],Sales!A:A,Sales!C:C) -> 9 | S12: =_xlfn.XLOOKUP(Table3[[#This Row],[Product Name]],Sales!A:A,Sales!D:D) -> 0.2 | T12: =_xlfn.XLOOKUP(Table3[[#This Row],[Product Name]],Sales!A:A,Sales!E:E) -> 85.3092
A13: 12 | B13: CA-2018-115812 | C13: 9 | D13: 6 | E13: 2018 | F13: Standard Class | G13: BH-11710 | H13: brosina hoffman | I13: Consumer | J13: United States-California-Los Angeles | K13: West | L13: 90032 | M13: TEC-PH-10002033 | N13: Technology | O13: Phones | P13: Konftel 250 Conference phone - Charcoal black | Q13: =_xlfn.XLOOKUP(Table3[[#This Row],[Product Name]],Sales!A:A,Sales!B:B) -> 911.424 | R13: =_xlfn.XLOOKUP(Table3[[#This Row],[Product Name]],Sales!A:A,Sales!C:C) -> 4 | S13: =_xlfn.XLOOKUP(Table3[[#This Row],[Product Name]],Sales!A:A,Sales!D:D) -> 0.2 | T13: =_xlfn.XLOOKUP(Table3[[#This Row],[Product Name]],Sales!A:A,Sales!E:E) -> 68.3568
... A102: 101 | B102: CA-2020-158568 | C102: 29 | D102: 8 | E102: 2020 | F102: Standard Class | G102: RB-19465 | H102: rick bensley | I102: Home Office | J102: United States-Illinois-Chicago | K102: Central | L102: 60610 | M102: TEC-AC-10001767 | N102: Technology | O102: Accessories | P102: SanDisk Ultra 64 GB MicroSDHC Class 10 Memory Card | Q102: =_xlfn.XLOOKUP(Table3[[#This Row],[Product Name]],Sales!A:A,Sales!B:B) -> 95.976 | R102: =_xlfn.XLOOKUP(Table3[[#This Row],[Product Name]],Sales!A:A,Sales!C:C) -> 3 | S102: =_xlfn.XLOOKUP(Table3[[#This Row],[Product Name]],Sales!A:A,Sales!D:D) -> 0.2 | T102: =_xlfn.XLOOKUP(Table3[[#This Row],[Product Name]],Sales!A:A,Sales!E:E) -> -10.7973
A103: null | B103: null | C103: null | D103: null | E103: null | F103: null | G103: null | H103: null | I103: null | J103: null | K103: null | L103: null | M103: null | N103: null | O103: null | P103: null | Q103: =_xlfn.XLOOKUP(Table3[[#This Row],[Product Name]],Sales!A:A,Sales!B:B) -> null | R103: =_xlfn.XLOOKUP(Table3[[#This Row],[Product Name]],Sales!A:A,Sales!C:C) -> null | S103: =_xlfn.XLOOKUP(Table3[[#This Row],[Product Name]],Sales!A:A,Sales!D:D) -> null | T103: =_xlfn.XLOOKUP(Table3[[#This Row],[Product Name]],Sales!A:A,Sales!E:E) -> null
A104: 102 | B104: CA-2020-158568 | C104: 29 | D104: 8 | E104: 2020 | F104: Standard Class | G104: RB-19465 | H104: rick bensley | I104: Home Office | J104: United States-Illinois-Chicago | K104: Central | L104: 60610 | M104: OFF-BI-10002609 | N104: Office Supplies | O104: Binders | P104: Avery Hidden Tab Dividers for Binding Systems | Q104: =_xlfn.XLOOKUP(Table3[[#This Row],[Product Name]],Sales!A:A,Sales!B:B) -> 1.788 | R104: =_xlfn.XLOOKUP(Table3[[#This Row],[Product Name]],Sales!A:A,Sales!C:C) -> 3 | S104: =_xlfn.XLOOKUP(Table3[[#This Row],[Product Name]],Sales!A:A,Sales!D:D) -> 0.8 | T104: =_xlfn.XLOOKUP(Table3[[#This Row],[Product Name]],Sales!A:A,Sales!E:E) -> -3.0396
A105: 103 | B105: CA-2020-129903 | C105: 1 | D105: 12 | E105: 2020 | F105: Second Class | G105: GZ-14470 | H105: gary zandusky | I105: Consumer | J105: United States-Minnesota-Rochester | K105: Central | L105: 55901 | M105: OFF-PA-10004040 | N105: Office Supplies | O105: Paper | P105: Universal Premium White Copier/Laser Paper (20Lb. and 87 Bright) | Q105: =_xlfn.XLOOKUP(Table3[[#This Row],[Product Name]],Sales!A:A,Sales!B:B) -> 23.92 | R105: =_xlfn.XLOOKUP(Table3[[#This Row],[Product Name]],Sales!A:A,Sales!C:C) -> 4 | S105: =_xlfn.XLOOKUP(Table3[[#This Row],[Product Name]],Sales!A:A,Sales!D:D) -> 0 | T105: =_xlfn.XLOOKUP(Table3[[#This Row],[Product Name]],Sales!A:A,Sales!E:E) -> 11.7208
A106: 104 | B106: US-2019-156867 | C106: 13 | D106: 11 | E106: 2019 | F106: Standard Class | G106: LC-16870 | H106: lena cacioppo | I106: Consumer | J106: United States-Colorado-Aurora | K106: West | L106: 80013 | M106: TEC-AC-10001552 | N106: Technology | O106: Accessories | P106: Logitech K350 2.4Ghz Wireless Keyboard | Q106: =_xlfn.XLOOKUP(Table3[[#This Row],[Product Name]],Sales!A:A,Sales!B:B) -> 238.896 | R106: =_xlfn.XLOOKUP(Table3[[#This Row],[Product Name]],Sales!A:A,Sales!C:C) -> 6 | S106: =_xlfn.XLOOKUP(Table3[[#This Row],[Product Name]],Sales!A:A,Sales!D:D) -> 0.2 | T106: =_xlfn.XLOOKUP(Table3[[#This Row],[Product Name]],Sales!A:A,Sales!E:E) -> -26.8758
A107: 105 | B107: US-2019-156867 | C107: 13 | D107: 11 | E107: 2019 | F107: Standard Class | G107: LC-16870 | H107: lena cacioppo | I107: Consumer | J107: United States-Colorado-Aurora | K107: West | L107: 80013 | M107: FUR-FU-10004006 | N107: Furniture | O107: Furnishings | P107: Deflect-o DuraMat Lighweight, Studded, Beveled Mat for Low Pile Carpeting | Q107: =_xlfn.XLOOKUP(Table3[[#This Row],[Product Name]],Sales!A:A,Sales!B:B) -> 102.36 | R107: =_xlfn.XLOOKUP(Table3[[#This Row],[Product Name]],Sales!A:A,Sales!C:C) -> 3 | S107: =_xlfn.XLOOKUP(Table3[[#This Row],[Product Name]],Sales!A:A,Sales!D:D) -> 0.2 | T107: =_xlfn.XLOOKUP(Table3[[#This Row],[Product Name]],Sales!A:A,Sales!E:E) -> -3.8385
A108: 106 | B108: US-2019-156867 | C108: 13 | D108: 11 | E108: 2019 | F108: Standard Class | G108: LC-16870 | H108: lena cacioppo | I108: Consumer | J108: United States-Colorado-Aurora | K108: West | L108: 80013 | M108: OFF-BI-10002794 | N108: Office Supplies | O108: Binders | P108: Avery Trapezoid Ring Binder, 3" Capacity, Black, 1040 sheets | Q108: =_xlfn.XLOOKUP(Table3[[#This Row],[Product Name]],Sales!A:A,Sales!B:B) -> 36.882 | R108: =_xlfn.XLOOKUP(Table3[[#This Row],[Product Name]],Sales!A:A,Sales!C:C) -> 3 | S108: =_xlfn.XLOOKUP(Table3[[#This Row],[Product Name]],Sales!A:A,Sales!D:D) -> 0.7 | T108: =_xlfn.XLOOKUP(Table3[[#This Row],[Product Name]],Sales!A:A,Sales!E:E) -> -25.8174
A109: 107 | B109: CA-2021-119004 | C109: 23 | D109: 11 | E109: 2021 | F109: Standard Class | G109: JM-15250 | H109: janet martin | I109: Consumer | J109: United States-North Carolina-Charlotte | K109: South | L109: 28205 | M109: TEC-AC-10003499 | N109: Technology | O109: Accessories | P109: Memorex Mini Travel Drive 8 GB USB 2.0 Flash Drive | Q109: =_xlfn.XLOOKUP(Table3[[#This Row],[Product Name]],Sales!A:A,Sales!B:B) -> 74.112 | R109: =_xlfn.XLOOKUP(Table3[[#This Row],[Product Name]],Sales!A:A,Sales!C:C) -> 8 | S109: =_xlfn.XLOOKUP(Table3[[#This Row],[Product Name]],Sales!A:A,Sales!D:D) -> 0.2 | T109: =_xlfn.XLOOKUP(Table3[[#This Row],[Product Name]],Sales!A:A,Sales!E:E) -> 17.6016
A110: 108 | B110: CA-2021-119004 | C110: 23 | D110: 11 | E110: 2021 | F110: Standard Class | G110: JM-15250 | H110: janet martin | I110: Consumer | J110: United States-North Carolina-Charlotte | K110: South | L110: 28205 | M110: TEC-PH-10002844 | N110: Technology | O110: Phones | P110: Speck Products Candyshell Flip Case | Q110: =_xlfn.XLOOKUP(Table3[[#This Row],[Product Name]],Sales!A:A,Sales!B:B) -> 27.992 | R110: =_xlfn.XLOOKUP(Table3[[#This Row],[Product Name]],Sales!A:A,Sales!C:C) -> 1 | S110: =_xlfn.XLOOKUP(Table3[[#This Row],[Product Name]],Sales!A:A,Sales!D:D) -> 0.2 | T110: =_xlfn.XLOOKUP(Table3[[#This Row],[Product Name]],Sales!A:A,Sales!E:E) -> 2.0994
A111: 109 | B111: CA-2021-119004 | C111: 23 | D111: 11 | E111: 2021 | F111: Standard Class | G111: JM-15250 | H111: janet martin | I111: Consumer | J111: United States-North Carolina-Charlotte | K111: South | L111: 28205 | M111: OFF-AR-10000390 | N111: Office Supplies | O111: Art | P111: Newell Chalk Holder | Q111: =_xlfn.XLOOKUP(Table3[[#This Row],[Product Name]],Sales!A:A,Sales!B:B) -> 3.304 | R111: =_xlfn.XLOOKUP(Table3[[#This Row],[Product Name]],Sales!A:A,Sales!C:C) -> 1 | S111: =_xlfn.XLOOKUP(Table3[[#This Row],[Product Name]],Sales!A:A,Sales!D:D) -> 0.2 | T111: =_xlfn.XLOOKUP(Table3[[#This Row],[Product Name]],Sales!A:A,Sales!E:E) -> 1.0738
A112: 110 | B112: CA-2019-129476 | C112: 15 | D112: 10 | E112: 2019 | F112: Standard Class | G112: PA-19060 | H112: pete armstrong | I112: Home Office | J112: United States-Illinois-Orland Park | K112: Central | L112: 60462 | M112: TEC-AC-10000844 | N112: Technology | O112: Accessories | P112: Logitech Gaming G510s - Keyboard | Q112: =_xlfn.XLOOKUP(Table3[[#This Row],[Product Name]],Sales!A:A,Sales!B:B) -> 339.96 | R112: =_xlfn.XLOOKUP(Table3[[#This Row],[Product Name]],Sales!A:A,Sales!C:C) -> 5 | S112: =_xlfn.XLOOKUP(Table3[[#This Row],[Product Name]],Sales!A:A,Sales!D:D) -> 0.2 | T112: =_xlfn.XLOOKUP(Table3[[#This Row],[Product Name]],Sales!A:A,Sales!E:E) -> 67.992
A113: 111 | B113: CA-2021-146780 | C113: 25 | D113: 12 | E113: 2021 | F113: Standard Class | G113: CV-12805 | H113: cynthia voltz | I113: Corporate | J113: United States-New York-New York City | K113: East | L113: 10035 | M113: FUR-FU-10001934 | N113: Furniture | O113: Furnishings | P113: Magnifier Swing Arm Lamp | Q113: =_xlfn.XLOOKUP(Table3[[#This Row],[Product Name]],Sales!A:A,Sales!B:B) -> 41.96 | R113: =_xlfn.XLOOKUP(Table3[[#This Row],[Product Name]],Sales!A:A,Sales!C:C) -> 2 | S113: =_xlfn.XLOOKUP(Table3[[#This Row],[Product Name]],Sales!A:A,Sales!D:D) -> 0 | T113: =_xlfn.XLOOKUP(Table3[[#This Row],[Product Name]],Sales!A:A,Sales!E:E) -> 10.9096
A114: 112 | B114: CA-2020-128867 | C114: 3 | D114: 11 | E114: 2020 | F114: Standard Class | G114: CL-12565 | H114: clay ludtke | I114: Consumer | J114: United States-Iowa-Urbandale | K114: Central | L114: 50322 | M114: OFF-AR-10000380 | N114: Office Supplies | O114: Art | P114: Hunt PowerHouse Electric Pencil Sharpener, Blue | Q114: =_xlfn.XLOOKUP(Table3[[#This Row],[Product Name]],Sales!A:A,Sales!B:B) -> 75.96 | R114: =_xlfn.XLOOKUP(Table3[[#This Row],[Product Name]],Sales!A:A,Sales!C:C) -> 2 | S114: =_xlfn.XLOOKUP(Table3[[#This Row],[Product Name]],Sales!A:A,Sales!D:D) -> 0 | T114: =_xlfn.XLOOKUP(Table3[[#This Row],[Product Name]],Sales!A:A,Sales!E:E) -> 22.788
A115: 113 | B115: CA-2020-128867 | C115: 3 | D115: 11 | E115: 2020 | F115: Standard Class | G115: CL-12565 | H115: clay ludtke | I115: Consumer | J115: United States-Iowa-Urbandale | K115: Central | L115: 50322 | M115: OFF-BI-10003981 | N115: Office Supplies | O115: Binders | P115: Avery Durable Plastic 1" Binders | Q115: =_xlfn.XLOOKUP(Table3[[#This Row],[Product Name]],Sales!A:A,Sales!B:B) -> 27.24 | R115: =_xlfn.XLOOKUP(Table3[[#This Row],[Product Name]],Sales!A:A,Sales!C:C) -> 6 | S115: =_xlfn.XLOOKUP(Table3[[#This Row],[Product Name]],Sales!A:A,Sales!D:D) -> 0 | T115: =_xlfn.XLOOKUP(Table3[[#This Row],[Product Name]],Sales!A:A,Sales!E:E) -> 13.3476
... A199: 197 | B199: CA-2018-140004 | C199: 21 | D199: 3 | E199: 2018 | F199: Standard Class | G199: CB-12025 | H199: cassandra brandow | I199: Consumer | J199: United States-Ohio-Hamilton | K199: East | L199: 45011 | M199: OFF-AR-10004027 | N199: Office Supplies | O199: Art | P199: Binney & Smith inkTank Erasable Desk Highlighter, Chisel Tip, Yellow, 12/Box | Q199: =_xlfn.XLOOKUP(Table3[[#This Row],[Product Name]],Sales!A:A,Sales!B:B) -> 6.048 | R199: =_xlfn.XLOOKUP(Table3[[#This Row],[Product Name]],Sales!A:A,Sales!C:C) -> 3 | S199: =_xlfn.XLOOKUP(Table3[[#This Row],[Product Name]],Sales!A:A,Sales!D:D) -> 0.2 | T199: =_xlfn.XLOOKUP(Table3[[#This Row],[Product Name]],Sales!A:A,Sales!E:E) -> 1.5876
A200: null | B200: null | C200: null | D200: null | E200: null | F200: null | G200: null | H200: null | I200: null | J200: null | K200: null | L200: null | M200: null | N200: null | O200: null | P200: null | Q200: =_xlfn.XLOOKUP(Table3[[#This Row],[Product Name]],Sales!A:A,Sales!B:B) -> null | R200: =_xlfn.XLOOKUP(Table3[[#This Row],[Product Name]],Sales!A:A,Sales!C:C) -> null | S200: =_xlfn.XLOOKUP(Table3[[#This Row],[Product Name]],Sales!A:A,Sales!D:D) -> null | T200: =_xlfn.XLOOKUP(Table3[[#This Row],[Product Name]],Sales!A:A,Sales!E:E) -> null
A201: 198 | B201: CA-2021-107720 | C201: 6 | D201: 11 | E201: 2021 | F201: Standard Class | G201: VM-21685 | H201: valerie mitchum | I201: Home Office | J201: United States-New Jersey-Westfield | K201: East | L201: 7090 | M201: OFF-ST-10001414 | N201: Office Supplies | O201: Storage | P201: Decoflex Hanging Personal Folder File | Q201: =_xlfn.XLOOKUP(Table3[[#This Row],[Product Name]],Sales!A:A,Sales!B:B) -> 46.26 | R201: =_xlfn.XLOOKUP(Table3[[#This Row],[Product Name]],Sales!A:A,Sales!C:C) -> 3 | S201: =_xlfn.XLOOKUP(Table3[[#This Row],[Product Name]],Sales!A:A,Sales!D:D) -> 0 | T201: =_xlfn.XLOOKUP(Table3[[#This Row],[Product Name]],Sales!A:A,Sales!E:E) -> 12.0276
A202: 199 | B202: US-2021-124303 | C202: 6 | D202: 7 | E202: 2021 | F202: Standard Class | G202: FH-14365 | H202: fred hopkins | I202: Corporate | J202: United States-Pennsylvania-Philadelphia | K202: East | L202: 19120 | M202: OFF-BI-10000343 | N202: Office Supplies | O202: Binders | P202: Pressboard Covers with Storage Hooks, 9 1/2" x 11", Light Blue | Q202: =_xlfn.XLOOKUP(Table3[[#This Row],[Product Name]],Sales!A:A,Sales!B:B) -> 2.946 | R202: =_xlfn.XLOOKUP(Table3[[#This Row],[Product Name]],Sales!A:A,Sales!C:C) -> 2 | S202: =_xlfn.XLOOKUP(Table3[[#This Row],[Product Name]],Sales!A:A,Sales!D:D) -> 0.7 | T202: =_xlfn.XLOOKUP(Table3[[#This Row],[Product Name]],Sales!A:A,Sales!E:E) -> -2.2586
A203: 200 | B203: US-2021-124303 | C203: 6 | D203: 7 | E203: 2021 | F203: Standard Class | G203: FH-14365 | H203: fred hopkins | I203: Corporate | J203: United States-Pennsylvania-Philadelphia | K203: East | L203: 19120 | M203: OFF-PA-10002749 | N203: Office Supplies | O203: Paper | P203: Wirebound Message Books, 5-1/2 x 4 Forms, 2 or 4 Forms per Page | Q203: =_xlfn.XLOOKUP(Table3[[#This Row],[Product Name]],Sales!A:A,Sales!B:B) -> 16.056 | R203: =_xlfn.XLOOKUP(Table3[[#This Row],[Product Name]],Sales!A:A,Sales!C:C) -> 3 | S203: =_xlfn.XLOOKUP(Table3[[#This Row],[Product Name]],Sales!A:A,Sales!D:D) -> 0.2 | T203: =_xlfn.XLOOKUP(Table3[[#This Row],[Product Name]],Sales!A:A,Sales!E:E) -> 5.8203
A204: 201 | B204: CA-2021-105074 | C204: 24 | D204: 6 | E204: 2021 | F204: Standard Class | G204: MB-17305 | H204: maria bertelson | I204: Consumer | J204: United States-Ohio-Akron | K204: East | L204: 44312 | M204: OFF-PA-10002666 | N204: Office Supplies | O204: Paper | P204: Southworth 25% Cotton Linen-Finish Paper & Envelopes | Q204: =_xlfn.XLOOKUP(Table3[[#This Row],[Product Name]],Sales!A:A,Sales!B:B) -> 21.744 | R204: =_xlfn.XLOOKUP(Table3[[#This Row],[Product Name]],Sales!A:A,Sales!C:C) -> 3 | S204: =_xlfn.XLOOKUP(Table3[[#This Row],[Product Name]],Sales!A:A,Sales!D:D) -> 0.2 | T204: =_xlfn.XLOOKUP(Table3[[#This Row],[Product Name]],Sales!A:A,Sales!E:E) -> 6.795
A205: 202 | B205: CA-2018-133690 | C205: 3 | D205: 8 | E205: 2018 | F205: First Class | G205: BS-11755 | H205: bruce stewart | I205: Consumer | J205: United States-Colorado-Denver | K205: West | L205: 80219 | M205: FUR-TA-10004289 | N205: Furniture | O205: Tables | P205: BoxOffice By Design Rectangular and Half-Moon Meeting Room Tables | Q205: =_xlfn.XLOOKUP(Table3[[#This Row],[Product Name]],Sales!A:A,Sales!B:B) -> 218.75 | R205: =_xlfn.XLOOKUP(Table3[[#This Row],[Product Name]],Sales!A:A,Sales!C:C) -> 2 | S205: =_xlfn.XLOOKUP(Table3[[#This Row],[Product Name]],Sales!A:A,Sales!D:D) -> 0.5 | T205: =_xlfn.XLOOKUP(Table3[[#This Row],[Product Name]],Sales!A:A,Sales!E:E) -> -161.875
A206: 203 | B206: CA-2018-133690 | C206: 3 | D206: 8 | E206: 2018 | F206: First Class | G206: BS-11755 | H206: bruce stewart | I206: Consumer | J206: United States-Colorado-Denver | K206: West | L206: 80219 | M206: OFF-AP-10003622 | N206: Office Supplies | O206: Appliances | P206: Bravo II Megaboss 12-Amp Hard Body Upright, Replacement Belts, 2 Belts per Pack | Q206: =_xlfn.XLOOKUP(Table3[[#This Row],[Product Name]],Sales!A:A,Sales!B:B) -> 2.6 | R206: =_xlfn.XLOOKUP(Table3[[#This Row],[Product Name]],Sales!A:A,Sales!C:C) -> 1 | S206: =_xlfn.XLOOKUP(Table3[[#This Row],[Product Name]],Sales!A:A,Sales!D:D) -> 0.2 | T206: =_xlfn.XLOOKUP(Table3[[#This Row],[Product Name]],Sales!A:A,Sales!E:E) -> 0.2925
A207: 204 | B207: US-2021-116701 | C207: 17 | D207: 12 | E207: 2021 | F207: Second Class | G207: LC-17140 | H207: logan currie | I207: Consumer | J207: United States-Texas-Dallas | K207: Central | L207: 75220 | M207: OFF-AP-10003217 | N207: Office Supplies | O207: Appliances | P207: Eureka Sanitaire Commercial Upright | Q207: =_xlfn.XLOOKUP(Table3[[#This Row],[Product Name]],Sales!A:A,Sales!B:B) -> 66.284 | R207: =_xlfn.XLOOKUP(Table3[[#This Row],[Product Name]],Sales!A:A,Sales!C:C) -> 2 | S207: =_xlfn.XLOOKUP(Table3[[#This Row],[Product Name]],Sales!A:A,Sales!D:D) -> 0.8 | T207: =_xlfn.XLOOKUP(Table3[[#This Row],[Product Name]],Sales!A:A,Sales!E:E) -> -178.9668
A208: 205 | B208: CA-2021-126382 | C208: 3 | D208: 6 | E208: 2021 | F208: Standard Class | G208: HK-14890 | H208: heather kirkland | I208: Corporate | J208: United States-Tennessee-Franklin | K208: South | L208: 37064 | M208: FUR-FU-10002960 | N208: Furniture | O208: Furnishings | P208: Eldon 200 Class Desk Accessories, Burgundy | Q208: =_xlfn.XLOOKUP(Table3[[#This Row],[Product Name]],Sales!A:A,Sales!B:B) -> 35.168 | R208: =_xlfn.XLOOKUP(Table3[[#This Row],[Product Name]],Sales!A:A,Sales!C:C) -> 7 | S208: =_xlfn.XLOOKUP(Table3[[#This Row],[Product Name]],Sales!A:A,Sales!D:D) -> 0.2 | T208: =_xlfn.XLOOKUP(Table3[[#This Row],[Product Name]],Sales!A:A,Sales!E:E) -> 9.6712
A209: 206 | B209: CA-2021-108329 | C209: 9 | D209: 12 | E209: 2021 | F209: Standard Class | G209: LE-16810 | H209: laurel elliston | I209: Consumer | J209: United States-California-Whittier | K209: West | L209: 90604 | M209: TEC-PH-10001918 | N209: Technology | O209: Phones | P209: Nortel Business Series Terminal T7208 Digital phone | Q209: =_xlfn.XLOOKUP(Table3[[#This Row],[Product Name]],Sales!A:A,Sales!B:B) -> 444.768 | R209: =_xlfn.XLOOKUP(Table3[[#This Row],[Product Name]],Sales!A:A,Sales!C:C) -> 4 | S209: =_xlfn.XLOOKUP(Table3[[#This Row],[Product Name]],Sales!A:A,Sales!D:D) -> 0.2 | T209: =_xlfn.XLOOKUP(Table3[[#This Row],[Product Name]],Sales!A:A,Sales!E:E) -> 44.4768
A210: 207 | B210: CA-2021-135860 | C210: 1 | D210: 12 | E210: 2021 | F210: Standard Class | G210: JH-15985 | H210: joseph holt | I210: Consumer | J210: United States-Michigan-Saginaw | K210: Central | L210: 48601 | M210: OFF-ST-10000642 | N210: Office Supplies | O210: Storage | P210: Tennsco Lockers, Gray | Q210: =_xlfn.XLOOKUP(Table3[[#This Row],[Product Name]],Sales!A:A,Sales!B:B) -> 83.92 | R210: =_xlfn.XLOOKUP(Table3[[#This Row],[Product Name]],Sales!A:A,Sales!C:C) -> 4 | S210: =_xlfn.XLOOKUP(Table3[[#This Row],[Product Name]],Sales!A:A,Sales!D:D) -> 0 | T210: =_xlfn.XLOOKUP(Table3[[#This Row],[Product Name]],Sales!A:A,Sales!E:E) -> 5.8744
A211: 208 | B211: CA-2021-135860 | C211: 1 | D211: 12 | E211: 2021 | F211: Standard Class | G211: JH-15985 | H211: joseph holt | I211: Consumer | J211: United States-Michigan-Saginaw | K211: Central | L211: 48601 | M211: TEC-PH-10001700 | N211: Technology | O211: Phones | P211: Panasonic KX-TG6844B Expandable Digital Cordless Telephone | Q211: =_xlfn.XLOOKUP(Table3[[#This Row],[Product Name]],Sales!A:A,Sales!B:B) -> 131.98 | R211: =_xlfn.XLOOKUP(Table3[[#This Row],[Product Name]],Sales!A:A,Sales!C:C) -> 2 | S211: =_xlfn.XLOOKUP(Table3[[#This Row],[Product Name]],Sales!A:A,Sales!D:D) -> 0 | T211: =_xlfn.XLOOKUP(Table3[[#This Row],[Product Name]],Sales!A:A,Sales!E:E) -> 35.6346
...

Sheet Sales
A1: Product Name | B1: Sales | C1: Quantity | D1: Discount | E1: Profit
A2: Bush Somerset Collection Bookcase | B2: 261.96 | C2: 2 | D2: 0 | E2: 41.9136
A3: Hon Deluxe Fabric Upholstered Stacking Chairs, Rounded Back | B3: 731.94 | C3: 3 | D3: 0 | E3: 219.582
A4: Self-Adhesive Address Labels for Typewriters by Universal | B4: 14.62 | C4: 2 | D4: 0 | E4: 6.8714
A5: Bretford CR4500 Series Slim Rectangular Table | B5: 957.5775 | C5: 5 | D5: 0.45 | E5: -383.031
A6: Eldon Fold 'N Roll Cart System | B6: 22.368 | C6: 2 | D6: 0.2 | E6: 2.5164
A7: Eldon Expressions Wood and Plastic Desk Accessories, Cherry Wood | B7: 48.86 | C7: 7 | D7: 0 | E7: 14.1694
A8: Newell 322 | B8: 7.28 | C8: 4 | D8: 0 | E8: 1.9656
A9: Mitel 5320 IP Phone VoIP phone | B9: 907.152 | C9: 6 | D9: 0.2 | E9: 90.7152
A10: DXL Angle-View Binders with Locking Rings by Samsill | B10: 18.504 | C10: 3 | D10: 0.2 | E10: 5.7825
A11: Belkin F5C206VTEL 6 Outlet Surge | B11: 114.9 | C11: 5 | D11: 0 | E11: 34.47
A12: Chromcraft Rectangular Conference Tables | B12: 1706.184 | C12: 9 | D12: 0.2 | E12: 85.3092
A13: Konftel 250 Conference phone - Charcoal black | B13: 911.424 | C13: 4 | D13: 0.2 | E13: 68.3568
... A102: SanDisk Ultra 64 GB MicroSDHC Class 10 Memory Card | B102: 95.976 | C102: 3 | D102: 0.2 | E102: -10.7973
A103: null | B103: null | C103: null | D103: null | E103: null
A104: Avery Hidden Tab Dividers for Binding Systems | B104: 1.788 | C104: 3 | D104: 0.8 | E104: -3.0396
A105: Universal Premium White Copier/Laser Paper (20Lb. and 87 Bright) | B105: 23.92 | C105: 4 | D105: 0 | E105: 11.7208
A106: Logitech K350 2.4Ghz Wireless Keyboard | B106: 238.896 | C106: 6 | D106: 0.2 | E106: -26.8758
A107: Deflect-o DuraMat Lighweight, Studded, Beveled Mat for Low Pile Carpeting | B107: 102.36 | C107: 3 | D107: 0.2 | E107: -3.8385
A108: Avery Trapezoid Ring Binder, 3" Capacity, Black, 1040 sheets | B108: 36.882 | C108: 3 | D108: 0.7 | E108: -25.8174
A109: Memorex Mini Travel Drive 8 GB USB 2.0 Flash Drive | B109: 74.112 | C109: 8 | D109: 0.2 | E109: 17.6016
A110: Speck Products Candyshell Flip Case | B110: 27.992 | C110: 1 | D110: 0.2 | E110: 2.0994
A111: Newell Chalk Holder | B111: 3.304 | C111: 1 | D111: 0.2 | E111: 1.0738
A112: Logitech Gaming G510s - Keyboard | B112: 339.96 | C112: 5 | D112: 0.2 | E112: 67.992
A113: Magnifier Swing Arm Lamp | B113: 41.96 | C113: 2 | D113: 0 | E113: 10.9096
A114: Hunt PowerHouse Electric Pencil Sharpener, Blue | B114: 75.96 | C114: 2 | D114: 0 | E114: 22.788
A115: Avery Durable Plastic 1" Binders | B115: 27.24 | C115: 6 | D115: 0 | E115: 13.3476
... A199: Binney & Smith inkTank Erasable Desk Highlighter, Chisel Tip, Yellow, 12/Box | B199: 6.048 | C199: 3 | D199: 0.2 | E199: 1.5876
A200: null | B200: null | C200: null | D200: null | E200: null
A201: Decoflex Hanging Personal Folder File | B201: 46.26 | C201: 3 | D201: 0 | E201: 12.0276
A202: Pressboard Covers with Storage Hooks, 9 1/2" x 11", Light Blue | B202: 2.946 | C202: 2 | D202: 0.7 | E202: -2.2586
A203: Wirebound Message Books, 5-1/2 x 4 Forms, 2 or 4 Forms per Page | B203: 16.056 | C203: 3 | D203: 0.2 | E203: 5.8203
A204: Southworth 25% Cotton Linen-Finish Paper & Envelopes | B204: 21.744 | C204: 3 | D204: 0.2 | E204: 6.795
A205: BoxOffice By Design Rectangular and Half-Moon Meeting Room Tables | B205: 218.75 | C205: 2 | D205: 0.5 | E205: -161.875
A206: Bravo II Megaboss 12-Amp Hard Body Upright, Replacement Belts, 2 Belts per Pack | B206: 2.6 | C206: 1 | D206: 0.2 | E206: 0.2925
A207: Eureka Sanitaire Commercial Upright | B207: 66.284 | C207: 2 | D207: 0.8 | E207: -178.9668
A208: Eldon 200 Class Desk Accessories, Burgundy | B208: 35.168 | C208: 7 | D208: 0.2 | E208: 9.6712
A209: Nortel Business Series Terminal T7208 Digital phone | B209: 444.768 | C209: 4 | D209: 0.2 | E209: 44.4768
A210: Tennsco Lockers, Gray | B210: 83.92 | C210: 4 | D210: 0 | E210: 5.8744
A211: Panasonic KX-TG6844B Expandable Digital Cordless Telephone | B211: 131.98 | C211: 2 | D211: 0 | E211: 35.6346
...
